Workbook

Sheet Summary
A1: CQ Formalization Overview
A2: Theme | B2: CQs formalized | C2: CQs not expressible | D2: Total CQs
A3: Land Use and Zoning | B3: =COUNTIF('Land Use and Zoning'!B6:B38,"<>") -> 31 | C3: =COUNTBLANK('Land Use and Zoning'!B6:B38) -> 2 | D3: =SUM(B3:C3) -> 33
A4: Development Feasibility | B4: =COUNTIF('Development Feasibility'!B6:B25,"<>") -> 20 | C4: =COUNTBLANK('Development Feasibility'!B6:B25) -> 0 | D4: =SUM(B4:C4) -> 20
A5: Development Desirability | B5: =COUNTIF('Development Desirability (Quali'!B6:B23,"<>") -> 17 | C5: =COUNTBLANK('Development Desirability (Quali'!B6:B23) -> 1 | D5: =SUM(B5:C5) -> 18
A6: Total | B6: =SUM(B3:B5) -> 68 | C6: =SUM(C3:C5) -> 3 | D6: =SUM(D3:D5) -> 71
A9: Implementation Notes:
A10: For many queries we may need to adjust so that some of the triples are optional (e.g. certain attributes are missing)
A11: Notes for some queries on open vs closed world assumption - e.g. we assume a parcel without any building / infrastructure is vacant but we could just be missing the data point
A12: There could also be vacant buildings (we don't currently have data on this)
A15: CQ Evaluation Overview
A16: Theme | B16: Pass | C16: Pass with missing data | D16: Pass with fault | E16: Incomplete (System error)
A17: Land Use and Zoning | B17: =COUNTIF('Land Use and Zoning'!D6:D38,"Pass") -> 24 | C17: =COUNTIF('Land Use and Zoning'!D6:D38,"Pass with missing data") -> 6 | D17: =COUNTIF('Land Use and Zoning'!D6:D38,"Pass with fault") -> 0 | E17: =COUNTIF('Land Use and Zoning'!D6:D38,"System error") -> 0 | F17: =SUM(B17:E17) -> 30 | G17: *2 not expressible
A18: Development Feasibility | B18: =COUNTIF('Development Feasibility'!D6:D25, "Pass") -> 17 | C18: =COUNTIF('Development Feasibility'!D6:D25, "Pass with missing data") -> 3 | D18: =COUNTIF('Development Feasibility'!D6:D25, "Pass with fault") -> 0 | E18: =COUNTIF('Development Feasibility'!D6:D25,"System error") -> 0 | F18: =SUM(B18:E18) -> 20
A19: Development Desirability | B19: =COUNTIF('Development Desirability (Quali'!C6:C23,"Pass") -> 15 | C19: =COUNTIF('Development Desirability (Quali'!C6:C23,"Pass with missing data") -> 2 | D19: =COUNTIF('Development Desirability (Quali'!C6:C23,"Pass with fault") -> 0 | E19: =COUNTIF('Development Desirability (Quali'!C6:C23,"System error") -> 0 | F19: =SUM(B19:E19) -> 17 | G19: *1 not expressible
A20: Total

Sheet Land Use and Zoning
A1: Flagged for validation exercise
A2: Omitted
A3: Failed to formalize
A4: CQ | B4: CQ Formalization | C4: Comments; Data availability | D4: Test
A5: Theme: Land Use and Zoning
A6: 1. Where in the city does there exist vacant parcels of land? | B6: SELECT ?x ?y WHERE { ?x a hp:Parcel. FILTER NOT EXISTS {?y a hp:Building; hp:occupies ?x} } | C6: not available | D6: Pass
A7: 1a. What is the size of the parcel? | B7: SELECT ?a ?u WHERE { ?p a hp:Parcel; hp:hasArea [i72:hasValue [i72:hasNumericalValue ?a; i72:hasUnit ?u]]. } | C7: computable (geof:metricArea) Consider whether it's better to store the values (shown here), or compute them on-the-fly with built-in functions (geoSPARQL) | D7: Pass
A8: 1b. What is the perimeter of the parcel? | B8: SELECT * WHERE { ?p a hp:Parcel; hp:hasPerimeter [i72:hasValue [i72:hasNumericalValue ?a; i72:hasUnit ?u]]. } | C8: alternatively, could be computed on import (mapping); seems less efficient (due to the number of parcels) so suggestion is to do this on demand as required for now | D8: Pass
A9: 2. Who owns parcel x? | B9: SELECT * WHERE { <http://ontology.eil.utoronto.ca/Toronto/Toronto#Property5230346> a hp:Parcel; hp:ownership ?o. } | C9: not available | D9: Pass
A10: 3. What use is parcel x zoned for, e.g., residential (single family, multifamily), commercial, mixed, industrial? | B10: SELECT * WHERE { <http://ontology.eil.utoronto.ca/Toronto/Toronto#Property5230346> a hp:Parcel; loc:hasLocation ?ploc. ?reg hp:definedFor [loc:hasLocation ?regloc]; hp:designatesZoningType [oz:allowsUse ?use]. #regulation applies to parcel's location ?ploc geo:sfWithin ?regloc. } | C10: available at a high level only (zoning type) | D10: Pass
A11: 3a. What is it currently being used for? | B11: SELECT * WHERE { # tor:Property5230346 a hp:Parcel. ?p a hp:Parcel. ?b hp:occupies ?p; bdg:use ?use. } | D11: Pass | E11: No data on actual land use; instead, we can query for the use of any buildings that occupy the parcel; Note: not all buildings have defined uses
A12: 3b. What is the current density of the neighbourhood? | B12: SELECT * WHERE { #if we are looking for the neighbourhood of a specific parcel <http://ontology.eil.utoronto.ca/Toronto/Toronto#Property5230346> loc:hasLocation ?ploc. ?x a cacensus:PopulationDensity2016; cacensus:hasLocation ?characteristic_area; i72:hasValue [i72:hasNumericalValue ?density; i72:hasUnit ?density_unit]. ?characteristic_area tor:inNeighborhood [loc_old:hasLocation ?nloc; rdfs:comment ?neighbourhood_name]. #find the neighbourhood the parcel is located in ?ploc geo:sfWithin ?nloc. } | C12: yes (census) | D12: Pass | E12: Note: neighbourhood-level estimates of the census characteristics aren't currently stored in the graph (this query returns the value for all census tracts in the neighbourhood). Will be incorporating neighbourhood-level estimates in the next iteration. | F12: Note: the census mapping defines the wrong unit for density (should be persons per square km)
A13: 7a. What regulations exist on setbacks from road or adjacent parcels? | B13: SELECT ?source ?limit ?unit ?constrained_class WHERE { #if we are looking for the neighbourhood of a specific parcel <http://ontology.eil.utoronto.ca/Toronto/Toronto#Property5230346> loc:hasLocation ?ploc. #regulations ?source hp:definesRegulation ?reg. ?source a hp:ZoningBylaw. #the regulation that designates the zoning type for an area ?reg a hp:Regulation; hp:definedFor ?area; hp:designatesZoningType ?zt. #the regulation that applies to a particular zoning type ?reg2 opr:forZoning ?zt; hp:specifiesConstraint [i72:hasValue [i72:hasNumericalValue ?limit; i72:hasUnit ?unit]; hp:constrains [i72:parameter_of_var [i72:hasName hp:hasSetback]; i72:minimum_of ?p]]. ?p rdf:type [i72:defined_by ?constrained_class]. #check for the population type (in case there is a regulation on another type of area) ?area loc:hasLocation ?loc. #regulations that apply to an area that the parcel is located in ?ploc geo:sfWithin ?loc. }" | C13: no data (potentially computable based on the combination of several maps including building topology) Note: this and following queries on regulations should be amended to include a clause restricting the regulation to be defined in a (the current) bylaw Note: this and following queries need to be fixed to refer to parcel geometries for sfWithin | D13: Pass with missing data | E13: No setback data
A14: 7b. What regulations exist on FSR (Floor Surface Ratio)? | B14: SELECT ?source ?limit ?unit ?constrained_class WHERE { #if we are looking for the neighbourhood of a specific parcel <http://ontology.eil.utoronto.ca/Toronto/Toronto#Property5230346> loc:hasLocation ?ploc. #regulations ?source hp:definesRegulation ?reg. ?source a hp:ZoningBylaw. #the regulation that designates the zoning type for an area ?reg a hp:Regulation; hp:definedFor [loc:hasLocation ?loc]; hp:designatesZoningType ?zt. #the regulation that applies to a particular zoning type ?reg2 opr:forZoning ?zt; hp:specifiesConstraint [i72:hasValue [i72:hasNumericalValue ?limit]; hp:constrains [i72:parameter_of_var [i72:hasName hp:hasFSI]; i72:maximum_of ?p]]. ?p rdf:type [i72:defined_by ?constrained_class]. #check for the population type (in case there is a regulation on another type of area) #regulations that apply to an area that the parcel is located in ?ploc geo:sfWithin ?loc. } | C14: yes | D14: Pass
A15: 7c. What height restriction exists? | B15: SELECT ?source ?reg ?limit ?unit WHERE { #if we are looking for the neighbourhood of a specific parcel <http://ontology.eil.utoronto.ca/Toronto/Toronto#Property5230346> loc:hasLocation ?ploc. #regulations ?source hp:definesRegulation ?reg. ?source a hp:ZoningBylaw. #the regulation that designates the zoning type for an area ?reg a hp:Regulation; hp:definedFor ?area; hp:specifiesConstraint [i72:hasValue [i72:hasNumericalValue ?limit; i72:hasUnit ?unit]; hp:constrains [i72:parameter_of_var [i72:hasName hp:hasBuildingHeight]; i72:maximumOf ?p]]. #consider check for the population type (in case there is a regulation on height of something else) ?area loc:hasLocation ?loc. #regulations that apply to an area that the parcel is located in ?ploc geo:sfWithin ?loc. } | D15: Pass
A16: 7d. What minimum lot size restriction exists? | B16: SELECT ?source ?limit ?unit ?constrained_class WHERE { #if we are looking for the neighbourhood of a specific parcel <http://ontology.eil.utoronto.ca/Toronto/Toronto#Property5230346> loc:hasLocation ?ploc. #regulations ?source hp:definesRegulation ?reg. ?source a hp:ZoningBylaw. #the regulation that designates the zoning type for an area ?reg a hp:Regulation; hp:definedFor ?area; hp:designatesZoningType ?zt. #the regulation that applies to a particular zoning type ?reg2 opr:forZoning ?zt; hp:specifiesConstraint [i72:hasValue [i72:hasNumericalValue ?limit; i72:hasUnit ?unit]; hp:constrains [i72:parameter_of_var [i72:hasName hp:hasArea]; i72:minimum_of ?p]]. ?p rdf:type [i72:defined_by ?constrained_class]. #check for the population type (in case there is a regulation on another type of area) ?area loc:hasLocation ?loc. #regulations that apply to an area that the parcel is located in ?ploc geo:sfWithin ?loc. } | D16: Pass | E16: Note: consider opportunities for reasoning that could simplify the query format required (we should be able to infer the area(s) that ?reg2 applies to, based on the area that ?reg is defined for)
A17: 7e. Are there any (building) shape restrictions on the parcel? | C17: Not expressible; ""shape restrictions"" not defined Data not available | D17: N/A
A18: 8a. How closely does recent development conform to setback regulations? | B18: SELECT DISTINCT ?nearbyp ?zstring ?ctlabel ?limit ?vunit ?actualvalue ?actualunit ?compliancestatus WHERE { #if we are looking for the neighbourhood of a specific parcel tor:Property5314508 loc:hasLocation [geo:asWKT ?pwkt]. #identify nearby parcels and attribute of interest ?nearbyp a hp:Parcel ; loc:hasLocation [geo:asWKT ?nearbypwkt]. #optional filter for "recent" development, e.g. buildings constructed after 2000? #?b a hp:Building; # hp:occupies ?nearbyp. #OPTIONAL {?b bdg:yearOfConstruction [time:year ?year]. # FILTER (?year > 2000)} FILTER( geof:distance(?pwkt, ?nearbypwkt, uom:metre) < 200 ) #zoning constraints that apply to nearby parcels ?nearbyp hp:zonedForConstraint ?c. #regulations defined in law ?reg hp:definedIn ?source. ?source a hp:ZoningBylaw. #the regulation that defines the constraint ?reg a hp:Regulation; hp:appliesTo [loc:hasLocation ?loc]; hp:specifiesConstraint ?c. ?c i72:hasValue ?v; hp:constrains [i72:parameter_of_var [i72:hasName hp:hasSetback]; i72:description_of ?p]; #constraint type rdf:type ?constraint_type. #constraint value ?v i72:hasNumericalValue ?limit. OPTIONAL {?v i72:hasUnit ?vunit. ?vunit rdfs:label ?unit.} OPTIONAL {?reg genprop:hasName ?zstring. } #zoning string label, if applicable #quantity constraint subtype (allowance, requirement, ...) to clarify the nature of the regulation ?constraint_type rdfs:subClassOf hp:QuantityConstraint; rdfs:label ?ctlabel. FILTER (?constraint_type != hp:QuantityConstraint) #the actual value of the constrained attribute for the parcel, if known OPTIONAL { ?nearbyp hp:hasSetback [i72:hasValue [i72:hasNumericalValue ?actualvalue; i72:hasUnit ?aunit]]. ?aunit rdfs:label ?actualunit. } #or, the actual value of the constrained attribute for the building, if known OPTIONAL { ?b hp:occupies ?nearbyp; hp:hasSetback [i72:hasValue [i72:hasNumericalValue ?actualvalue; i72:hasUnit ?aunit]]. ?aunit rdfs:label ?actualunit. } #logic to define a new column to identify whether a constraint is violated BIND(xsd:double(?actualvalue) AS ?numActual) BIND(xsd:double(?limit) AS ?numLimit)BIND(COALESCE( IF(!BOUND(?numActual) || !BOUND(?numLimit), "unknown", IF(BOUND(?vunit) && BOUND(?aunit) && ?vunit != ?aunit, "incompatible units", IF(?constraint_type = hp:QuantityAllowance, IF(?numActual > ?numLimit, "noncompliant", "compliant"), IF(?constraint_type = hp:QuantityRequirement, IF(?numActual < ?numLimit, "noncompliant", "compliant"), IF(?constraint_type = hp:QuantityEquivalence, IF(?numActual != ?numLimit, "noncompliant", "compliant"), "unknown" ) ) ) ) ), "unknown" ) AS ?compliancestatus) } | C18: TODO: add date filter to identify *recent* development for this and following CQs | D18: Pass with no data
A19: 8b How closely does recent development conform to FSR regulations? | B19: SELECT DISTINCT ?nearbyp ?zstring ?ctlabel ?limit ?vunit ?actualvalue ?actualunit ?compliancestatus WHERE { #if we are looking for the neighbourhood of a specific parcel tor:Property5314508 loc:hasLocation [geo:asWKT ?pwkt]. #identify nearby parcels and attribute of interest ?nearbyp a hp:Parcel ; loc:hasLocation [geo:asWKT ?nearbypwkt]. #optional filter for "recent" development, e.g. buildings constructed after 2000? #?b a hp:Building; # hp:occupies ?nearbyp. #OPTIONAL {?b bdg:yearOfConstruction [time:year ?year]. # FILTER (?year > 2000)} FILTER( geof:distance(?pwkt, ?nearbypwkt, uom:metre) < 200 ) #zoning constraints that apply to nearby parcels ?nearbyp hp:zonedForConstraint ?c. #regulations defined in law ?reg hp:definedIn ?source. ?source a hp:ZoningBylaw. #the regulation that defines the constraint ?reg a hp:Regulation; hp:appliesTo [loc:hasLocation ?loc]; hp:specifiesConstraint ?c. ?c i72:hasValue ?v; hp:constrains [i72:parameter_of_var [i72:hasName hp:hasFSI]; i72:description_of ?p]; #constraint type rdf:type ?constraint_type. #constraint value ?v i72:hasNumericalValue ?limit. OPTIONAL {?v i72:hasUnit ?vunit. ?vunit rdfs:label ?unit.} OPTIONAL {?reg genprop:hasName ?zstring. } #zoning string label, if applicable #quantity constraint subtype (allowance, requirement, ...) to clarify the nature of the regulation ?constraint_type rdfs:subClassOf hp:QuantityConstraint; rdfs:label ?ctlabel. FILTER (?constraint_type != hp:QuantityConstraint) #the actual value of the constrained attribute for the parcel, if known OPTIONAL { ?nearbyp hp:hasFSI [i72:hasValue [i72:hasNumericalValue ?actualvalue; i72:hasUnit ?aunit]]. ?aunit rdfs:label ?actualunit. } #or, the actual value of the constrained attribute for the building, if known OPTIONAL { ?b hp:occupies ?nearbyp; hp:hasFSI [i72:hasValue [i72:hasNumericalValue ?actualvalue; i72:hasUnit ?aunit]]. ?aunit rdfs:label ?actualunit. } #logic to define a new column to identify whether a constraint is violated BIND(xsd:double(?actualvalue) AS ?numActual) BIND(xsd:double(?limit) AS ?numLimit)BIND(COALESCE( IF(!BOUND(?numActual) || !BOUND(?numLimit), "unknown", IF(BOUND(?vunit) && BOUND(?aunit) && ?vunit != ?aunit, "incompatible units", IF(?constraint_type = hp:QuantityAllowance, IF(?numActual > ?numLimit, "noncompliant", "compliant"), IF(?constraint_type = hp:QuantityRequirement, IF(?numActual < ?numLimit, "noncompliant", "compliant"), IF(?constraint_type = hp:QuantityEquivalence, IF(?numActual != ?numLimit, "noncompliant", "compliant"), "unknown" ) ) ) ) ), "unknown" ) AS ?compliancestatus) } | D19: Pass
A20: 8c How closely does recent development conform to height restrictions? | B20: SELECT DISTINCT ?nearbyp ?zstring ?ctlabel ?limit ?vunit ?actualvalue ?actualunit ?compliancestatus WHERE { #if we are looking for the neighbourhood of a specific parcel tor:Property5314508 loc:hasLocation [geo:asWKT ?pwkt]. #identify nearby parcels and attribute of interest ?nearbyp a hp:Parcel ; loc:hasLocation [geo:asWKT ?nearbypwkt]. #optional filter for "recent" development, e.g. buildings constructed after 2000? #?b a hp:Building; # hp:occupies ?nearbyp. #OPTIONAL {?b bdg:yearOfConstruction [time:year ?year]. # FILTER (?year > 2000)} FILTER( geof:distance(?pwkt, ?nearbypwkt, uom:metre) < 200 ) #zoning constraints that apply to nearby parcels ?nearbyp hp:zonedForConstraint ?c. #regulations defined in law ?reg hp:definedIn ?source. ?source a hp:ZoningBylaw. #the regulation that defines the constraint ?reg a hp:Regulation; hp:appliesTo [loc:hasLocation ?loc]; hp:specifiesConstraint ?c. ?c i72:hasValue ?v; hp:constrains [i72:parameter_of_var [i72:hasName hp:hasBuildingHeight]; i72:description_of ?p]; #constraint type rdf:type ?constraint_type. #constraint value ?v i72:hasNumericalValue ?limit. OPTIONAL {?v i72:hasUnit ?vunit. ?vunit rdfs:label ?unit.} OPTIONAL {?reg genprop:hasName ?zstring. } #zoning string label, if applicable #quantity constraint subtype (allowance, requirement, ...) to clarify the nature of the regulation ?constraint_type rdfs:subClassOf hp:QuantityConstraint; rdfs:label ?ctlabel. FILTER (?constraint_type != hp:QuantityConstraint) #the actual value of the constrained attribute for the parcel, if known OPTIONAL { ?nearbyp hp:hasBuildingHeight [i72:hasValue [i72:hasNumericalValue ?actualvalue; i72:hasUnit ?aunit]]. ?aunit rdfs:label ?actualunit. } #or, the actual value of the constrained attribute for the building, if known OPTIONAL { ?b hp:occupies ?nearbyp; hp:hasBuildingHeight [i72:hasValue [i72:hasNumericalValue ?actualvalue; i72:hasUnit ?aunit]]. ?aunit rdfs:label ?actualunit. } #logic to define a new column to identify whether a constraint is violated BIND(xsd:double(?actualvalue) AS ?numActual) BIND(xsd:double(?limit) AS ?numLimit)BIND(COALESCE( IF(!BOUND(?numActual) || !BOUND(?numLimit), "unknown", IF(BOUND(?vunit) && BOUND(?aunit) && ?vunit != ?aunit, "incompatible units", IF(?constraint_type = hp:QuantityAllowance, IF(?numActual > ?numLimit, "noncompliant", "compliant"), IF(?constraint_type = hp:QuantityRequirement, IF(?numActual < ?numLimit, "noncompliant", "compliant"), IF(?constraint_type = hp:QuantityEquivalence, IF(?numActual != ?numLimit, "noncompliant", "compliant"), "unknown" ) ) ) ) ), "unknown" ) AS ?compliancestatus) } | D20: Pass
A21: 8d. How closely does recent development conform to minimum lot size restrictions? | B21: SELECT DISTINCT ?nearbyp ?zstring ?ctlabel ?limit ?vunit ?actualvalue ?actualunit ?compliancestatus WHERE { #if we are looking for the neighbourhood of a specific parcel tor:Property5314508 loc:hasLocation [geo:asWKT ?pwkt]. #identify nearby parcels and attribute of interest ?nearbyp a hp:Parcel ; loc:hasLocation [geo:asWKT ?nearbypwkt]. #optional filter for "recent" development, e.g. buildings constructed after 2000? #?b a hp:Building; # hp:occupies ?nearbyp. #OPTIONAL {?b bdg:yearOfConstruction [time:year ?year]. # FILTER (?year > 2000)} FILTER( geof:distance(?pwkt, ?nearbypwkt, uom:metre) < 200 ) #zoning constraints that apply to nearby parcels ?nearbyp hp:zonedForConstraint ?c. #regulations defined in law ?reg hp:definedIn ?source. ?source a hp:ZoningBylaw. #the regulation that defines the constraint ?reg a hp:Regulation; hp:appliesTo [loc:hasLocation ?loc]; hp:specifiesConstraint ?c. ?c i72:hasValue ?v; hp:constrains [i72:parameter_of_var [i72:hasName hp:hasArea]; i72:description_of ?p]; #constraint type rdf:type ?constraint_type. #constraint value ?v i72:hasNumericalValue ?limit. OPTIONAL {?v i72:hasUnit ?vunit. ?vunit rdfs:label ?unit.} OPTIONAL {?reg genprop:hasName ?zstring. } #zoning string label, if applicable #quantity constraint subtype (allowance, requirement, ...) to clarify the nature of the regulation ?constraint_type rdfs:subClassOf hp:QuantityConstraint; rdfs:label ?ctlabel. FILTER (?constraint_type != hp:QuantityConstraint) #the actual value of the constrained attribute for the parcel, if known OPTIONAL { ?nearbyp hp:hasArea [i72:hasValue [i72:hasNumericalValue ?actualvalue; i72:hasUnit ?aunit]]. ?aunit rdfs:label ?actualunit. } #or, the actual value of the constrained attribute for the building, if known OPTIONAL { ?b hp:occupies ?nearbyp; hp:hasArea [i72:hasValue [i72:hasNumericalValue ?actualvalue; i72:hasUnit ?aunit]]. ?aunit rdfs:label ?actualunit. } #logic to define a new column to identify whether a constraint is violated BIND(xsd:double(?actualvalue) AS ?numActual) BIND(xsd:double(?limit) AS ?numLimit)BIND(COALESCE( IF(!BOUND(?numActual) || !BOUND(?numLimit), "unknown", IF(BOUND(?vunit) && BOUND(?aunit) && ?vunit != ?aunit, "incompatible units", IF(?constraint_type = hp:QuantityAllowance, IF(?numActual > ?numLimit, "noncompliant", "compliant"), IF(?constraint_type = hp:QuantityRequirement, IF(?numActual < ?numLimit, "noncompliant", "compliant"), IF(?constraint_type = hp:QuantityEquivalence, IF(?numActual != ?numLimit, "noncompliant", "compliant"), "unknown" ) ) ) ) ), "unknown" ) AS ?compliancestatus) } | C21: revise not about the building about about the size of the lot it's on -- looking at (changes to) the actual parcels (where there has been recent development) | D21: Pass
A22: 8e. How closely does recent development conform to shape restrictions? | C22: Not expressible; "shape restrictions" not defined
A23: 16. How many dwellings occupy the parcel? | B23: SELECT * WHERE { <http://ontology.eil.utoronto.ca/Toronto/Toronto#Property5230346> a hp:Parcel; loc:hasLocation ?ploc. ?plot geo:asWKT ?pwkt. ?char a cacensus:TotalPrivateDwellings2016; cacensus:hasLocation ?ct; i72:hasValue [i72:hasNumericalValue ?num_dwellings]. ?ct loc_old:hasLocation ?ctloc. ?ctloc geo:asWKT ?ctwkt. ?ploc geo:sfWithin ?ctloc. BIND((geoext:area(?pwkt)/geoext:area(?ctwkt)) AS ?percent_area) BIND((?num_dwellings * ?percent_area) AS ?est_num_dwellngs) } | C23: not available at the parcel level, could attempt a rough approximation based on census numbers | D23: Pass | E23: Don't have parcel-level data but we can estimate based on the ratio of the parcel's area to the area of its census tract. (i.e., as was done with neighbourhoods)
A24: 17. How many residents occupy the parcel? | B24: SELECT * WHERE { <http://ontology.eil.utoronto.ca/Toronto/Toronto#Property5230346> a hp:Parcel; loc:hasLocation ?ploc. ?plot geo:asWKT ?pwkt. ?char a cacensus:Population2016; cacensus:hasLocation ?ct; i72:hasValue [i72:hasNumericalValue ?num_dwellings]. ?ct loc_old:hasLocation ?ctloc. ?ctloc geo:asWKT ?ctwkt. ?ploc geo:sfWithin ?ctloc. BIND((geoext:area(?pwkt)/geoext:area(?ctwkt)) AS ?percent_area) BIND((?num_dwellings * ?percent_area) AS ?est_num_dwellngs) } | C24: not available at the parcel level, could attempt a rough approximation based on census numbers | D24: Pass | E24: as above
A25: 24b.What density policies apply to a parcel of land? | B25: SELECT ?source ?limit ?unit ?constrained_class WHERE { #if we are looking for the neighbourhood of a specific parcel <http://ontology.eil.utoronto.ca/Toronto/Toronto#Property5230346> loc:hasLocation ?ploc. #regulations ?source hp:definesRegulation ?reg. ?source a hp:ZoningBylaw. #the regulation that designates the zoning type for an area ?reg a hp:Regulation; hp:definedFor [loc:hasLocation ?loc]; hp:designatesZoningType ?zt. #the regulation that applies to a particular zoning type ?reg2 opr:forZoning ?zt; hp:specifiesConstraint [i72:hasValue [i72:hasNumericalValue ?limit]; hp:constrains [i72:parameter_of_var [i72:hasName hp:hasFSI]; i72:maximum_of ?p]]. ?p rdf:type [i72:defined_by ?constrained_class]. #check for the population type (in case there is a regulation on another type of area) #regulations that apply to an area that the parcel is located in ?ploc geo:sfWithin ?loc. } | C25: (Duplicate of 7b) Beyond this, we'd need an understanding and specification of what qualifies as a density policy (e.g. land use types) | D25: Pass | F25: Duplicate of 7b Consider modifying this to retrieve all density-related policies on, e.g. max units, max height
A26: 24c. Does the parcel have the potential for mixed use development? Note: this is a variation on CQ-3 | B26: ASK { <http://ontology.eil.utoronto.ca/Toronto/Toronto#Property5230346> a hp:Parcel; loc:hasLocation ?ploc. #should specify reg defined in bylaw ?reg hp:definedFor [loc:hasLocation ?regloc]. #regulation applies to parcel's location ?ploc geo:sfWithin ?regloc. ?reg hp:designatesZoningType [oz:allowsUse ?use]. FILTER(?use="<http://ontology.eil.utoronto.ca/Toronto/Toronto#MixedUseResidential") } | C26: Note: it is difficult to query "mixed use" specifically, unless that is part of the land use code system being used | D26: Pass | E26: Near repeat of CQ3; Note - unclear why but specifying tor:MixedUseResidential directly in the pattern with oz:allowsUse causes the query to time out.
A27: 31. What publicly owned parcels of land are available for current or future development? | B27: SELECT ?parcel WHERE { ?parcel hp:ownership [a org_city:GovernmentOrganization]. FILTER NOT EXISTS {?x hp:occupies ?parcel} } | C27: "vacant, publicly owned land" | D27: Pass | E27: Interpreted as "parcels that are not currently occupied by infrastructure"; beyond that it's hard to answer the question - what are the factors that make something available? (e.g. vacant, underused, …)
A28: 32c. What is the planned zoning for the parcel? What is the planned land use for the parcel? | B28: SELECT * WHERE { <http://ontology.eil.utoronto.ca/Toronto/Toronto#Property5230346> a hp:Parcel; loc:hasLocation ?ploc. ?reg hp:definedFor [loc:hasLocation ?regloc]; hp:definedIn [a hp:Plan]; hp:designatesZoningType [oz:allowsUse ?use]. #regulation applies to parcel's location ?ploc geo:sfWithin ?regloc. } | C28: not available | D28: Pass with missing data | E28: Near repeat of CQ3
A29: 37. What is the zoned capacity for a parcel of land? | B29: SELECT ?source ?limit ?unit ?constrained_class WHERE { #if we are looking for the neighbourhood of a specific parcel <http://ontology.eil.utoronto.ca/Toronto/Toronto#Property5230346> loc:hasLocation ?ploc. #regulations ?source hp:definesRegulation ?reg. ?source a hp:ZoningBylaw. #the regulation that designates the zoning type for an area ?reg a hp:Regulation; hp:definedFor [loc:hasLocation ?loc]; hp:designatesZoningType ?zt. #the regulation that applies to a particular zoning type ?reg2 opr:forZoning ?zt; hp:specifiesConstraint [i72:hasValue [i72:hasNumericalValue ?limit; i72:hasUnit ?unit]; hp:constrains [i72:parameter_of_var [i72:hasName hp:hasNumDwellings]; i72:minimum_of ?p]]. ?p rdf:type [i72:defined_by ?constrained_class]. #check for the population type (in case there is a regulation on another type of area) #regulations that apply to an area that the parcel is located in ?ploc geo:sfWithin ?loc. } | C29: max number dwelling units | D29: Pass with missing data | E29: Note: the "units" field (for capacity per parcel) is included in the bylaw datset but the data is not currently populated
A30: 40. What is the zoning of nearby parcels (note, this is a minor deviation from #3) | B30: SELECT ?nearbyp ?zt WHERE { #if we are looking for the neighbourhood of a specific parcel tor:Property5314508 loc:hasLocation [geo:asWKT ?pwkt]. #identify nearby parcels and attribute of interest ?nearbyp a hp:Parcel ; loc:hasLocation [geo:asWKT ?nearbypwkt]. FILTER( geof:distance(?pwkt, ?nearbypwkt, uom:metre) < 200 ) #zoning constraints that apply to nearby parcels ?nearbyp hp:zonedAsType ?zt. } | C30: <- note: hasGeometry should be replaced with hasLocation for now | D30: Pass
A31: 41. Is the parcel currently occupied by any building(s)? | B31: ASK { ?b hp:occupies <http://ontology.eil.utoronto.ca/Toronto/Toronto#Property5230346>; a hp:Building. } | D31: Pass
A32: 41a. If so, what is the age and condition of the building? | B32: SELECT * { ?b hp:occupies <http://ontology.eil.utoronto.ca/Toronto/Toronto#Property5230346>; a hp:Building; bdg:yearOfConstruction [time:year ?year]. OPTIONAL {?b hp:hasCondition [code:hasCode [genprop:hasName ?condition]]} } | D32: Pass | E32: No condition data
A33: 41b. Does the building have occupants? | B33: SELECT * { ?b hp:occupies <http://ontology.eil.utoronto.ca/Toronto/Toronto#Property5230346>; a hp:Building. OPTIONAL {?b hp:occupiedBy ?o} } | D33: Pass with missing data | E33: No building occupancy data available; no synthetic data created
A34: 50. What vacant land does the federal government own? Which part of government owns it? (variation on CQ1) | B34: SELECT ?parcel ?gov_unit WHERE { ?parcel hp:ownership hp:governmentofcanada. ?gov_unit org:unit_of hp:governmentofcanada. FILTER NOT EXISTS {?x hp:occupies ?parcel} } | D34: Pass | E34: Near repeat of 31; Note no federally owned land captured in the dataset
A35: 53. What buildings does the federal government own? | B35: #assume hpcdm:can_federal_government is the identifier for the Federal Government SELECT ?building WHERE { ?building hp:ownership hp:governmentofcanada. } | D35: Pass with missing data | E35: No building ownership data; no synthetic data created
A36: 54. Is the building vacant? Underutilized? | B36: SELECT * WHERE {{ ?building hp:ownership hp:governmentofcanada FILTER NOT EXISTS {?building hp:occupiedBy ?o} } UNION { ?building hp:ownership hp:governmentofcanada FILTER NOT EXISTS {?building bdg:hasBuildingUnit [hp:occupiedBy ?o]} }} | D36: Pass with missing data
A37: 56. What is the current use of the building? | B37: SELECT * WHERE { <http://ontology.eil.utoronto.ca/Toronto/Toronto#Buildinga9257bf45927fdbceba349ee083dd0dd> bdg:use ?use. } | D37: Pass
A38: 57. What is the building zoned for? | B38: SELECT * WHERE { <http://ontology.eil.utoronto.ca/Toronto/Toronto#Buildinga9257bf45927fdbceba349ee083dd0dd> hp:occupies ?p. ?p loc:hasLocation ?ploc. ?ploc geo:sfIntersects ?regloc. ?source hp:definesRegulation ?reg. ?source a hp:ZoningBylaw. ?reg a hp:Regulation; hp:definedFor [loc:hasLocation ?regloc]; hp:designatesZoningType [oz:allowsUse ?landuse] } | D38: Pass | E38: Note: this instance required the use of sfIntersects; for more complete results we need to run multiple versions of these queries with sfWithin, sfIntersects

Sheet Development Feasibility
A1: Flagged for validation exercise
A2: Omitted
A3: Failed to formalize
A4: CQ | B4: SPARQL | C4: Notes (general and data availability) | D4: Result
A5: Development Feasibility
A6: 4. Does there exist any issues with the parcel, such as prior use (e.g., gas station, industrial waste) requiring remediation? | B6: ASK { <http://ontology.eil.utoronto.ca/Toronto/Toronto#Property5230346> hp:hasDevelopmentClassification tor:brownfield } | C6: would be interesting to investigate inference of these types; currently, the definition is open-ended; we'd need to introduce a type system to implement this (if the data is available); alternatively, we could formulate the query by looking at the history of the parcels' land use | D6: Pass with missing data | E6: No data (synthetic data on development classifications not created) | F6: In the absence of a dataset on development classifications, future work should look at defining inference rules based on historical parcel use (though without historical land use data this would also not be sufficient)
A7: 5. Is the parcel accessible directly by road? | B7: SELECT * { <http://ontology.eil.utoronto.ca/Toronto/Toronto#Property5230346> loc:hasLocation ?ploc. ?ploc geo:asWKT ?pwkt. ?road a <http://ontology.eil.utoronto.ca/CDT/RoadLink>; loc:hasLocation ?roadloc. ?roadloc geo:asWKT ?swkt. BIND(geof:distance(?pwkt, ?swkt, uom:metre) AS ?distance) FILTER(?distance <= 20) } | C7: A few ways to compute this: true if the parcel has an address; true if the geometry intersects with a road segment's geometry, … | D7: Pass | E7: Future work: add rule to enable rules of the form: ASK WHERE { <parcel>hp:hasRoadAccess "true"^^xsd:boolean } | F7: Estimated based on min distance of 20 m.
A8: 5a. Fire and emergency access? | B8: SELECT ?s WHERE { #?p a <http://ontology.eil.utoronto.ca/HPCDM/Parcel>. <http://ontology.eil.utoronto.ca/Toronto/Toronto#Property5254870> loc:hasLocation ?p_loc. ?s a hp:FireEmergencyService; service:hasCatchmentArea ?s_loc. # the geometry of the parcel is within the geometry of the catchment area ?p_loc geo:sfWithin ?s_loc. } | C8: firestation (first response) catchment area data | D8: Pass | E8: Randomly selected parcel
A9: 6a. Is the parcel serviced by water? | B9: ASK { <http://ontology.eil.utoronto.ca/Toronto/Toronto#Property5254870> loc:hasLocation ?ploc. ?ploc geo:asWKT ?pwkt. ?s a hp:WaterService; hp:providedFromSite [loc:hasLocation ?sloc]. ?sloc geo:asWKT ?swkt. #(shortest) distance between the edge of the parcel and the service network BIND(geof:distance(?pwkt, ?swkt, uom:metre) AS ?distance) #limit distance to 30m FILTER (?distance <= 30) } | C9: The general query form assumes the existence of (implicit) catchment areas for water service. There is available data on the watermains (https://open.toronto.ca/dataset/watermains/) but service information at the parcel level is not defined. How could it be approximated? * intersect the watermain geometry with the road network (check if there is a watermain on the road segment corresponding to the parcel's address) * use the "location description" field (but this is subject to errors as it is just a street name) * calculate the distance between the parcel's centre to a point on the watermain and infer service based on some "reasonable" limit; the center point may not always be appropriate (e.g. for very large lots) but is more conservative than measuring to the boundary | D9: Pass | E9: Approximation (without catchment areas or parcel-level service data)
A10: 6b. Is the parcel serviced by wastewater? | B10: ASK { <http://ontology.eil.utoronto.ca/Toronto/Toronto#Property5254870> loc:hasLocation ?ploc. ?ploc geo:asWKT ?pwkt. ?s a hp:WastewaterService; hp:providedFromSite [loc:hasLocation ?sloc]. ?sloc geo:asWKT ?swkt. #(shortest) distance between the edge of the parcel and the service network BIND(geof:distance(?pwkt, ?swkt, uom:metre) AS ?distance) #limit distance to 30m FILTER (?distance <= 30) } | C10: Query assumes the existence of (implicit) catchment areas for wastewater service. There is available data on sewers (https://open.toronto.ca/dataset/sewer-gravity-mains/) but service information at the parcel level is not defined. How could it be approximated? * intersect the sewer geometry with the road network (check if there is a sewer on the stret where the parcel is located) * use the "location description" field (but this is subject to errors as it is just a street name) * calculate the distance between a point on the parcels' boundary to a point on the watermain and infer service based on some "reasonable" limit | D10: Pass | E10: Note: need to correct mapping (currently uses the class name "WasteWaterService"
A11: 6c. Is the parcel serviced by electricity? | B11: ASK { <http://ontology.eil.utoronto.ca/Toronto/Toronto#Property5437657> hp:servicedBy ?s; a hp:AdministrativeArea. ?s a hp:ElectricService. } | C11: toronto hydro substation capacity data ontario service area: https://experience.arcgis.com/experience/710b2687d8eb403a9163d7fbd0e09432/ | D11: Pass
A12: 9. How close are burdensome facilities (industrial plants, burdensome services, roads of supra-local significance)? | B12: SELECT * WHERE { <http://ontology.eil.utoronto.ca/Toronto/Toronto#Property5230346> a hp:Parcel; loc:hasLocation ?ploc. ?ploc geo:asWKT ?pwkt. ?reg hp:definedFor [loc:hasLocation [geo:asWKT ?regwkt]]; hp:designatesZoningType [oz:allowsUse <http://ontology.eil.utoronto.ca/Toronto/Toronto#HeavyIndustrialUses>]. #distance to locations allowing heavy industrial uses BIND(geof:distance(?pwkt, ?regwkt, uom:metre) AS ?distance) } SELECT * WHERE { <http://ontology.eil.utoronto.ca/Toronto/Toronto#Property5230346> a hp:Parcel; loc:hasLocation ?ploc. ?ploc geo:asWKT ?pwkt. ?road a <http://ontology.eil.utoronto.ca/CDT/RoadLink>; <http://ontology.eil.utoronto.ca/CDT/hasRoadClass> [code:hasCode [genprop:hasName ?road_class]]; loc:hasLocation [geo:asWKT ?rwkt]. FILTER ((?road_class ="Expressway / Highway")|| (?road_class="Freeway")) #ideally should use the code instead of name as a filter here #distance to locations allowing heavy industrial uses BIND(geof:distance(?pwkt, ?rwkt, uom:metre) AS ?distance) } | D12: Pass | E12: No data on use (can query for industrial zoning regulations instead) E.g. use http://ontology.eil.utoronto.ca/Toronto/Toronto#HeavyIndustrialUses in this query | F12: SELECT ?p ?dist WHERE {{ ?p hpcdm:use ex:industrial #example of industrial land use instance 5087-1:hasLocation [5087-1:hasGeometry ?g1]. <parcel> 5087-1:hasLocation [5087-1:hasGeometry ?g2]. BIND (geof:distance(?g1, ?g2, uom:metre) AS ?dist) } UNION { <parcel> 5087-1:hasLocation [5087-1:hasGeometry ?g2]. ?p a 5087-2:RoadSegment; cdt:hasRoadClass ex:highway. #note: road class individuals TBD BIND (geof:distance(?g1, ?g2, uom:metre) AS ?dist) } }
A13: 10a. What is the capacity for schools to absorb increases in population? | B13: SELECT ?s ?cap_avail WHERE { <http://ontology.eil.utoronto.ca/Toronto/Toronto#Property5230346> loc:hasLocation [geo:asWKT ?pwkt]. ?s a hp:SchoolService; hp:providedFromSite [loc:hasLocation [geo:asWKT ?swkt]]. # the geometry of the parcel is within a 400m distance #(shortest) distance between the edge of the parcel and the service network BIND(geof:distance(?pwkt, ?swkt, uom:metre) AS ?distance) #limit distance to 1500m FILTER (?distance <= 1500) ?s res:capacityInUse [i72:hasValue [i72:hasNumericalValue ?c_use]]. ?s res:hasCapacity [i72:hasValue [i72:hasNumericalValue ?c]]. BIND((?c - ?c_use) AS ?cap_avail) } | C13: Note: for this and similar queries - there is the possibility to query for hasAvailableCapacity and/or to compute the difference between the hasCapacity and hasCapacityInUse values (the best implementation might account for both) | D13: Pass | E13: Note: query is for "nearby" schools in the absence of catchment area data | F13: Some mapping errors to be resolved
A14: 10b. What is the capacity for water services to absorb increases in population? | B14: SELECT * WHERE { <http://ontology.eil.utoronto.ca/Toronto/Toronto#Property5230346> loc:hasLocation ?ploc. ?ws a hp:WaterService. ?ws service:hasCatchmentArea [loc:hasLocation ?cloc]. ?ploc geo:sfWithin ?cloc. ?ws res:hasAvailableCapacity [i72:hasValue [i72:hasNumericalValue ?avail_cap; i72:hasUnit ?unit]] } | C14: We don't have catchment area data for water services, but we could ask: what is the capacity for "nearby services" to absorb increases in population? Need to do some reasoning on the relationship between services at different levels; e.g. to which sub-services does a site of a service belong? | D14: Pass
A15: 10c. What is the capacity for wastewater to absorb increases in population? | B15: SELECT ?s ?cap_avail WHERE { <http://ontology.eil.utoronto.ca/Toronto/Toronto#Property5230346> loc:hasLocation [geo:asWKT ?pwkt]. ?s a hp:WasteWaterService; hp:providedFromSite [loc:hasLocation [geo:asWKT ?swkt]]. # the geometry of the parcel is within a 400m distance #(shortest) distance between the edge of the parcel and the service network BIND(geof:distance(?pwkt, ?swkt, uom:metre) AS ?distance) #limit distance to 1500m FILTER (?distance <= 1500) ?s res:capacityInUse [i72:hasValue [i72:hasNumericalValue ?c_use]]. ?s res:hasCapacity [i72:hasValue [i72:hasNumericalValue ?c]]. BIND((?c - ?c_use) AS ?cap_avail) } | D15: Pass | E15: Nearby service (sewer lines) approximation; no catchment area capacities
A16: 10d. What is the capacity for transport to absorb increases in population? | B16: SELECT * { <http://ontology.eil.utoronto.ca/Toronto/Toronto#Property5230346> loc:hasLocation ?ploc. ?ploc geo:asWKT ?pwkt. ?road a <http://ontology.eil.utoronto.ca/CDT/RoadLink>; loc:hasLocation ?roadloc. ?roadloc geo:asWKT ?swkt. BIND(geof:distance(?pwkt, ?swkt, uom:metre) AS ?distance) FILTER(?distance <= 5000) ?road res:hasAvailableCapacity [i72:hasValue [i72:hasNumericalValue ?available_capacity; i72:hasUnit ?capacity_unit]]. } | C16: The detailed answer to this question is complicated and likely requires some modelling and simulation. The system-level answer may not be particularly useful. We can interpret a simplified version of this as: what is the available capacity of nearby elements of the transportation (road) network? | D16: Pass | E16: Note: update to align with other service patterns
A17: 11a. What is the population of the neighbourhood? | B17: SELECT * WHERE { #if we are looking for the neighbourhood of a specific parcel <http://ontology.eil.utoronto.ca/Toronto/Toronto#Property5230346> loc:hasLocation ?ploc. #characteristic values for census tracts within a neighbourhood ?x a cacensus:Population2016; cacensus:hasLocation ?characteristic_area; i72:hasValue [i72:hasNumericalValue ?population; i72:hasUnit ?unit]. ?characteristic_area tor:inNeighborhood [loc_old:hasLocation ?nloc; rdfs:comment ?neighbourhood_name]. #find the neighbourhood the parcel is located in ?ploc geo:sfWithin ?nloc. } | C17: Note: this query is implemented with a toronto specific term tor:Neighbourhood (as not all places have formally defined neighbourhoods); this data is not available directly in the census but may be approximated through an approximation of census tract data according to neighbourhood location. (For a more precise answer, the question may be posed according to census tract(s)) Note: the data has already been instantiated witht he census namespace (it has not been mapped to the specialized subclasses defined in the hpcdm) | D17: Pass | E17: Note: consider where to implement census characteristic aggregation at the neighbourhood (or arbitrary area) level
A18: 11b. What is the annual income (average) of the neighbourhood? | B18: SELECT * WHERE { #if we are looking for the neighbourhood of a specific parcel <http://ontology.eil.utoronto.ca/Toronto/Toronto#Property5230346> loc:hasLocation ?ploc. #characteristic values for census tracts within a neighbourhood ?x a cacensus:AverageAfterTaxIncome25Sample2016; cacensus:hasLocation ?characteristic_area; i72:hasValue [i72:hasNumericalValue ?average_income; i72:hasUnit ?unit]. ?characteristic_area tor:inNeighborhood [loc_old:hasLocation ?nloc; rdfs:comment ?neighbourhood_name]. #find the neighbourhood the parcel is located in ?ploc geo:sfWithin ?nloc. } | C18: census data | D18: Pass
A19: 11c. What is the average rooms per home in the neighbourhood? | B19: SELECT * WHERE { #if we are looking for the neighbourhood of a specific parcel <http://ontology.eil.utoronto.ca/Toronto/Toronto#Property5230346> loc:hasLocation ?ploc. #characteristic values for census tracts within a neighbourhood ?x a cacensus:AverageNumberOfRoomsPerDwelling2016; cacensus:hasLocation ?characteristic_area; i72:hasValue [i72:hasNumericalValue ?rooms_per_dwelling; i72:hasUnit ?unit]. ?characteristic_area tor:inNeighborhood [loc_old:hasLocation ?nloc; rdfs:comment ?neighbourhood_name]. #find the neighbourhood the parcel is located in ?ploc geo:sfWithin ?nloc. } | C19: census data | D19: Pass
A20: 11d. What is the average land per home in the neighbourhood? | B20: SELECT (AVG(?area) AS ?averageArea) ?unit WHERE{{ SELECT ?nloc WHERE { <http://ontology.eil.utoronto.ca/Toronto/Toronto#Property5230346> loc:hasLocation ?ploc. ?n a tor:Neighborhood; loc_old:hasLocation ?nloc. ?ploc geo:sfWithin ?nloc. }} ?p a hp:Parcel; loc:hasLocation ?np; hp:hasArea [i72:hasValue [i72:hasNumericalValue ?area; i72:hasUnit ?unit]]. ?np geo:sfWithin ?nloc. } GROUP BY ?unit | C20: TBD: what are we really asking? Total land / num dwelling units in an area? Average parcel size? Total land / num buildings in an area? Formalized here as average parcel area (of all parcels occupied by some dwelling unit) in the area Average parcel size not available in census data but could be computed and stored in the graph, or possibly computed in the SPARQL query directly An alternative would be to (pre-)compute and store the parcel size averages, then access as: #format if average parcel area is computed and stored (as with census data) SELECT ?n ?pop WHERE { <parcel> 5087-1:hasLocation [5087-1:hasGeometry ?g1]. ?n a tor:Neighbourhood; 5087-2:hasLocation [5087-1:hasGeometry ?g2]. ?g1 geo:sfWithin ?g2. ?pop_i a hpcem:AverageParcelSize; census:hasLocation ?n; 21972:hasValue [21972:hasNumericalValue ?pop]. } ***Note: missing a filter here: we don't necessarily want the average of all of the parcels, just the ones where homes are built -- either restrict by residential landuse or by parcel type | D20: Pass
A21: 28c. Is the area currently serviced by electricity? What is the capacity? | B21: SELECT ?servicelabel ?avail_cap_type ?cap ?avail_cap_type ?cap_unit WHERE { #services with suitable catchment areas <http://ontology.eil.utoronto.ca/Toronto/Toronto#Property5437657> hp:servicedBy ?s; a hp:AdministrativeArea. ?s a hp:ElectricService. #service site location, if defined OPTIONAL { ?s hp:providedFromSite ?site. ?site loc:hasLocation ?sloc. ?sloc geo:asWKT ?swkt.} #service capacity ?s res:hasAvailableCapacity ?avail_cap. ?avail_cap i72:hasValue [i72:hasNumericalValue ?cap; i72:hasUnit ?cap_unit]; rdf:type ?avail_cap_type. # Filter out the "Generics" (owl:Thing and owl:Nothing) FILTER(?avail_cap_type != owl:Thing && ?avail_cap_type != owl:Nothing) FILTER(!isBlank(?avail_cap_type)) # The Leaf Constraint: # Ensure there isn't another type on this node that is a SUBCLASS of our candidate. FILTER NOT EXISTS { ?avail_cap rdf:type ?moreSpecific . ?moreSpecific rdfs:subClassOf+ ?avail_cap_type . # Standard safety filters FILTER(?moreSpecific != ?avail_cap_type) FILTER(?moreSpecific != owl:Nothing) } } | C21: some overlap with 6c Request for available capacity in progress with Toronto Hydro | D21: Pass
A22: 28d. Is the area currently serviced by waste disposal? What is the capacity? | B22: SELECT ?s ?wkt_s ?cap ?unit WHERE { <parcel> loc:hasLocation ?loc_p. ?loc_p geo:asWKT ?wkt_p. ?s a hp:SolidWasteService; service:hasCatchmentArea ?loc_s. ?loc_s geo:asWKT ?wkt_s. # the geometry of the parcel is within the geometry of the catchment area ?loc_p geo:sfWithin ?loc_s. #capacity ?s res:hasCapacity [i72:hasValue [i72:hasNumericalValue ?cap; i72:hasUnit ?unit]]. } | D22: Pass
A23: 28f. Is the area currently serviced by fire and emergency services? What is the capacity? | B23: SELECT ?s ?capacity ?capacity_use ?unit WHERE { #?p a <http://ontology.eil.utoronto.ca/HPCDM/Parcel>. <http://ontology.eil.utoronto.ca/Toronto/Toronto#Property5254870> loc:hasLocation ?p_loc. ?s a hp:FireEmergencyService; service:hasCatchmentArea ?s_loc; res:hasCapacity [i72:hasValue [i72:hasNumericalValue ?capacity; i72:hasUnit ?unit]]; res:capacityInUse [i72:hasValue [i72:hasNumericalValue ?capacity_use; i72:hasUnit ?unit]]. # the geometry of the parcel is within the geometry of the catchment area ?p_loc geo:sfWithin ?s_loc. } | D23: Pass
A24: 35a. For a parcel of land: What public utilities currently service the area? What is the capacity? What are the future expansion plans? | B24: SELECT ?s WHERE { #check for nearby service site locations { <http://ontology.eil.utoronto.ca/Toronto/Toronto#Property5254870> loc:hasLocation [geo:asWKT ?pwkt]. ?s a hp:Utility; hp:providedFromSite [loc:hasLocation [geo:asWKT ?swkt]]; res:hasCapacity [i72:hasValue [i72:hasNumericalValue ?capacity; i72:hasUnit ?unit]]. OPTIONAL { ?s hp:hasPlannedCapacity [i72:hasValue [i72:hasNumericalValue ?planned_capacity; i72:hasUnit ?unit]]. } BIND(geof:distance(?pwkt, ?swkt, uom:metre) AS ?distance) #"in the area" 400m FILTER(?distance <= 400) } UNION #check for nearby catchment areas { <http://ontology.eil.utoronto.ca/Toronto/Toronto#Property5254870> loc:hasLocation [geo:asWKT ?pwkt]. ?s a hp:Utility; service:hasCatchmentArea [geo:asWKT ?swkt]; res:hasCapacity [i72:hasValue [i72:hasNumericalValue ?capacity; i72:hasUnit ?unit]]. OPTIONAL { ?s hp:hasPlannedCapacity [i72:hasValue [i72:hasNumericalValue ?planned_capacity; i72:hasUnit ?unit]]. } BIND(geof:distance(?pwkt, ?swkt, uom:metre) AS ?distance) #"in the area" 400m FILTER(?distance <= 400) } } | D24: Pass with missing data
A25: 37a. How do stated zoning capacities differ with the capacities of built projects over the past X years? | B25: SELECT ?source ?limit ?unit ?constrained_class WHERE { #if we are looking for the neighbourhood of a specific parcel <http://ontology.eil.utoronto.ca/Toronto/Toronto#Property5230346> loc:hasLocation ?ploc. #regulations ?source hp:definesRegulation ?reg. ?source a hp:ZoningBylaw. #the regulation that designates the zoning type for an area ?reg a hp:Regulation; hp:definedFor ?area; hp:designatesZoningType ?zt. #the regulation that applies to a particular zoning type ?reg2 opr:forZoning ?zt; hp:specifiesConstraint [i72:hasValue [i72:hasNumericalValue ?limit; i72:hasUnit ?unit]; hp:constrains [i72:parameter_of_var [i72:hasName tor:hasNumDwellings]; i72:maximum_of ?p]]. ?p rdf:type [i72:defined_by ?constrained_class]. #check for the population type (in case there is a regulation on another type of area) ?area loc:hasLocation ?loc. #regulations that apply to an area that the parcel is located in ?ploc geo:sfWithin ?loc. #estimated actual number of dwellings ?char a cacensus:TotalPrivateDwellings2016; cacensus:hasLocation ?ct; i72:hasValue [i72:hasNumericalValue ?num_dwellings]. ?ct loc_old:hasLocation ?ctloc. ?ctloc geo:asWKT ?ctwkt. ?ploc geo:sfWithin ?ctloc. BIND((geoext:area(?pwkt)/geoext:area(?ctwkt)) AS ?percent_area) BIND((?num_dwellings * ?percent_area) AS ?est_num_dwellngs) } | D25: Pass with missing data | E25: Uses approximation of dwellings on a parcel (as in CQ 16); Missing max number of dwellings (units) from bylaw data (defined but not populated)

Sheet Development Desirability (Quali
A1: Flagged for validation exercise
A2: Omitted
A3: Failed to formalize
A4: CQ
A5: Development desirability (quality)
A6: 12. What is the amenity score for the parcel? | C6: not expressible directly, but a score could be computed based on distance measures (e.g. see queries on distance to specific types of amenities)
A7: 12a. Is it 15 minutes to transportation? | B7: ASK { <http://ontology.eil.utoronto.ca/Toronto/Toronto#Property5230346> loc:hasLocation [geo:asWKT ?pwkt]. tor:ttc cdt:providesService ?s. ?s hp:providedFromSite [loc:hasLocation [geo:asWKT ?swkt]] FILTER(geof:distance(?pwkt, ?swkt, uom:metre) < 400) #within 400m } | C7: Pass | D7: using a proxy of 400 m interpreted as public transport (transit system) Query simplified once mapping is corrected
A8: 12b. Is it 15 minutes to schools? (What schools are in the area?) What is their capacity? What is their planned capacity? | B8: #15min to schools? ask { <http://ontology.eil.utoronto.ca/Toronto/Toronto#Property5230346> loc:hasLocation [geo:asWKT ?pwkt]. ?s a hp:SchoolService. ?s hp:providedFromSite [loc:hasLocation [geo:asWKT ?swkt]] FILTER(geof:distance(?pwkt, ?swkt, uom:metre) < 400) #within 400m # ?s res:hasCapacity [i72:hasValue [i72:hasNumericalValue ?capacity]] } #schools in the area (1.5km) and capacity select * { <http://ontology.eil.utoronto.ca/Toronto/Toronto#Property5230346> loc:hasLocation [geo:asWKT ?pwkt]. ?s a hp:SchoolService. ?s hp:providedFromSite [loc:hasLocation [geo:asWKT ?swkt]] FILTER(geof:distance(?pwkt, ?swkt, uom:metre) < 1500) #within 400m ?s res:hasCapacity [i72:hasValue [i72:hasNumericalValue ?capacity]] OPTIONAL { ?s hp:hasPlannedCapacity [i72:hasValue [i72:hasNumericalValue ?plannedcapacity]] } } | C8: Pass
A9: 12c. Is it 15 minutes to food? | B9: ASK { <http://ontology.eil.utoronto.ca/Toronto/Toronto#Property5230346> loc:hasLocation [geo:asWKT ?pwkt]. ?s a cdt:SupermarketService. ?s hp:providedFromSite [loc:hasLocation [geo:asWKT ?swkt]] FILTER(geof:distance(?pwkt, ?swkt, uom:metre) < 400) #within 400m } | C9: Pass
A10: 12d. Is it 15 minutes to medical services? (What medical facilities and pharmacies are in the area?) What is their capacity? What is their planned capacity? | B10: select * { <http://ontology.eil.utoronto.ca/Toronto/Toronto#Property5230346> loc:hasLocation [geo:asWKT ?pwkt]. ?s a hp:HospitalService. ?s hp:providedFromSite [loc:hasLocation [geo:asWKT ?swkt]]. FILTER(geof:distance(?pwkt, ?swkt, uom:metre) < 40000) #within 4000m OPTIONAL {?s res:hasCapacity [i72:hasValue [i72:hasNumericalValue ?capacity; i72:hasUnit ?unit]]} OPTIONAL {?s res:capacityInUse [i72:hasValue [i72:hasNumericalValue ?usedcapacity; i72:hasUnit ?unit]]} OPTIONAL { ?s hp:hasPlannedCapacity [i72:hasValue [i72:hasNumericalValue ?plannedcapacity]] } } | C10: Pass | D10: Note: capacity data is incomplete - only hospitals are captured (not all medical facilities) to-date
A11: 12e. Is it 15 minutes to parks? (What parks are in the area?) What is their planned capacity? | B11: select * { <http://ontology.eil.utoronto.ca/Toronto/Toronto#Property5230346> loc:hasLocation [geo:asWKT ?pwkt]. ?s a cdt:ParkService. ?s hp:providedFromSite [loc:hasLocation [geo:asWKT ?swkt]]. FILTER(geof:distance(?pwkt, ?swkt, uom:metre) < 400) #within 400m ?s res:hasCapacity [i72:hasValue [i72:hasNumericalValue ?capacity; i72:hasUnit ?capacity_unit]]. OPTIONAL { ?s hp:hasPlannedCapacity [i72:hasValue [i72:hasNumericalValue ?plannedcapacity]] } } | C11: Pass
A12: 12f. Is it 15 minutes to libraries? (What libraries are in the area?) What is their capacity? What is their planned capacity? | B12: SELECT * WHERE { <http://ontology.eil.utoronto.ca/Toronto/Toronto#Property5230346> loc:hasLocation [geo:asWKT ?pwkt]. #temporary until mapping issues resolved ?x a <http://ontology.eil.utoronto.ca/CDT/Library>; <http://ontology.eil.utoronto.ca/CDT/providesService> ?s. ?s hp:providedFromSite [loc:hasLocation [geo:asWKT ?swkt]]. FILTER(geof:distance(?pwkt, ?swkt, uom:metre) < 400) #within 400m ?s res:hasCapacity [i72:hasValue [i72:hasNumericalValue ?capacity; i72:hasUnit ?capacity_unit]]. OPTIONAL { ?s hp:hasPlannedCapacity [i72:hasValue [i72:hasNumericalValue ?plannedcapacity]] } } | C12: Pass
A13: 13. What support services exist for lower income families? | B13: SELECT * { <http://ontology.eil.utoronto.ca/Toronto/Toronto#Property5230346> loc:hasLocation [geo:asWKT ?pwkt]. ?s a hp:LowIncomeSupportService. ?s hp:providedFromSite [loc:hasLocation [geo:asWKT ?swkt]]. FILTER(geof:distance(?pwkt, ?swkt, uom:metre) < 400) #within 400m } | C13: Pass
A14: 13a. Community centre/programmes | B14: select * { <http://ontology.eil.utoronto.ca/Toronto/Toronto#Property5230346> loc:hasLocation [geo:asWKT ?pwkt]. ?s a hp:CommunityCentreService. ?s hp:providedFromSite [loc:hasLocation [geo:asWKT ?swkt]]. FILTER(geof:distance(?pwkt, ?swkt, uom:metre) < 400) #within 400m ?s res:hasCapacity [i72:hasValue [i72:hasNumericalValue ?capacity; i72:hasUnit ?capacity_unit]]. OPTIONAL { ?s hp:hasPlannedCapacity [i72:hasValue [i72:hasNumericalValue ?plannedcapacity]] } } | C14: Pass
A15: 13e. Senior services/home care | B15: select * { <http://ontology.eil.utoronto.ca/Toronto/Toronto#Property5230346> loc:hasLocation [geo:asWKT ?pwkt]. ?s a hp:SeniorCareService. ?s hp:providedFromSite [loc:hasLocation [geo:asWKT ?swkt]]. FILTER(geof:distance(?pwkt, ?swkt, uom:metre) < 400) #within 400m ?s res:hasCapacity [i72:hasValue [i72:hasNumericalValue ?capacity; i72:hasUnit ?capacity_unit]]. OPTIONAL { ?s hp:hasPlannedCapacity [i72:hasValue [i72:hasNumericalValue ?plannedcapacity]] } } | C15: Pass
A16: 29b. What parks are in the area? What is their capacity? | B16: select * { <http://ontology.eil.utoronto.ca/Toronto/Toronto#Property5230346> loc:hasLocation [geo:asWKT ?pwkt]. ?s a cdt:ParkService. ?s hp:providedFromSite [loc:hasLocation [geo:asWKT ?swkt]]. FILTER(geof:distance(?pwkt, ?swkt, uom:metre) < 1000) #within 1000m ?s res:hasCapacity [i72:hasValue [i72:hasNumericalValue ?capacity; i72:hasUnit ?capacity_unit]]. OPTIONAL { ?s hp:hasPlannedCapacity [i72:hasValue [i72:hasNumericalValue ?plannedcapacity]] } } | C16: Pass | D16: Aside - this is a near duplicate of 12e; changed distance to 1km
A17: 29d. What childcare facilities are in the area? What is their capacity? What is their planned capacity? | B17: select * { <http://ontology.eil.utoronto.ca/Toronto/Toronto#Property5230346> loc:hasLocation [geo:asWKT ?pwkt]. ?s a hp:ChildcareService. ?s hp:providedFromSite [loc:hasLocation [geo:asWKT ?swkt]]. FILTER(geof:distance(?pwkt, ?swkt, uom:metre) < 1000) #within 2000m ?s res:hasCapacity [i72:hasValue [i72:hasNumericalValue ?capacity; i72:hasUnit ?capacity_unit]]. OPTIONAL { ?s hp:hasPlannedCapacity [i72:hasValue [i72:hasNumericalValue ?plannedcapacity]] } } | C17: Pass
A18: 30a. What are the plans for greenspace in the area? | B18: select * { <http://ontology.eil.utoronto.ca/Toronto/Toronto#Property5230346> loc:hasLocation [geo:asWKT ?pwkt]. ?reg a hp:Regulation; # hp:definedIn [a hpcdm:Plan]; #ideally, we'd have some more attributes to identify the plan(s) of interest hp:definedFor [loc:hasLocation [geo:asWKT ?regwkt]]; hp:designatesZoningType [oz:allowsUse <http://ontology.eil.utoronto.ca/Toronto/Toronto#NaturalConservationAreas>]. FILTER(geof:distance(?pwkt, ?regwkt, uom:metre) < 4000) #within 400m } | C18: Pass with missing data | D18: tested the query for any regulation, including planned regulations (not specifically for plans)
A19: 30b. What is the planned density for the area? | B19: SELECT ?source ?limit ?unit ?constrained_class WHERE { #if we are looking for the neighbourhood of a specific parcel <http://ontology.eil.utoronto.ca/Toronto/Toronto#Property5230346> loc:hasLocation ?ploc. #regulations ?source hp:definesRegulation ?reg. ?source a hp:Plan. ?reg a hp:Regulation; hp:definedFor [loc:hasLocation ?loc]; hp:specifiesConstraint [i72:hasValue [i72:hasNumericalValue ?limit]; hp:constrains [i72:parameter_of_var [i72:hasName hp:hasFSI]; i72:maximum_of ?p]]. ?p rdf:type [i72:defined_by ?constrained_class]. #check for the population type (in case there is a regulation on another type of area) #regulations that apply to an area that the parcel is located in ?ploc geo:sfWithin ?loc. } | C19: Pass with missing data | D19: Note: interpreted as FSI-density here but could also be interpreted as a planned value of persons per area
A20: 64. Is the vacant land close to a population centre? | B20: SELECT * WHERE { <http://ontology.eil.utoronto.ca/Toronto/Toronto#Property5230346> loc:hasLocation [geo:asWKT ?pwkt]. ?popctr a cacensus:PopulationCentre; loc:hasLocation [geo:asWKT ?popctrwkt]. BIND(geof:distance(?pwkt, ?popctrwkt, uom:metre) AS ?dist) FILTER(?dist < 5000) #within 5km } | C20: Pass
A21: 66. Is the vacant land close to employment opportunities? | B21: SELECT ?nearbyuse WHERE {{ <http://ontology.eil.utoronto.ca/Toronto/Toronto#Building3efdd236cedae97c4e70c81227035d4a> loc:hasLocation [geo:asWKT ?pwkt]. ?s a hp:Building; hp:occupies [loc:hasLocation [geo:asWKT ?nearbywkt]]; bdg:use ?nearbyuse. FILTER ((?nearbyuse != <http://ontology.eil.utoronto.ca/Toronto/Toronto#BuildingUseHouse>) || (?nearbyuse != <http://ontology.eil.utoronto.ca/Toronto/Toronto#BuildingUseHighRiseApartment>) || (?nearbyuse != <http://ontology.eil.utoronto.ca/Toronto/Toronto#BuildingUseLowRiseApartment>)) FILTER(geof:distance(?pwkt, ?nearbywkt, uom:metre) < 400) #within 400m } UNION { <http://ontology.eil.utoronto.ca/Toronto/Toronto#Property5230346> loc:hasLocation [geo:asWKT ?pwkt]. #regulations ?source hp:definesRegulation ?reg. ?source a hp:ZoningBylaw. ?reg a hp:Regulation; hp:definedFor [loc:hasLocation [geo:asWKT ?regwkt]]; hp:designatesZoningType [oz:allowsUse ?nearbyuse]. FILTER(geof:distance(?pwkt, ?regwkt, uom:metre) < 4000) #within 400m FILTER ((?nearbyuse != <http://ontology.eil.utoronto.ca/Toronto/Toronto#Residential>)||(?use != <http://ontology.eil.utoronto.ca/Toronto/Toronto#Residential>)) #all uses except residential might constitute employment opportunities #alternatively, could filter specifically for e.g. office or industrial type use } } | C21: Pass | D21: Note: filter values may vary. Per feedback from validation - it may be better to filter for "all except residential-type uses"
